Workbook

Sheet Portada
A1: Seguridad e Higiene Laboral: análisis de la accidentabilidad en la industria de Misiones y su relación con el sistema de ART (2021-2025)
A3: Título del trabajo | B3: Seguridad e Higiene Laboral: análisis de la accidentabilidad en la industria de Misiones y su relación con el sistema de ART (2021-2025)
A4: Objetivo del libro | B4: Analizar la evolución de la accidentabilidad laboral en la provincia de Misiones entre 2021 y 2025 con estadísticas de la SRT y otras fuentes identificadas, y establecer un marco comparativo con los datos nacionales de la industria manufacturera.
A5: Período de análisis | B5: 2021-2025
A6: Alcance geográfico | B6: Provincia de Misiones (datos parciales) y total nacional (industria manufacturera y total del sistema) como marco comparativo.
A7: Carrera | B7: Seguridad e Higiene Laboral
A8: Autor/a | B8: Macarena Soledad Veron
A9: Fecha de elaboración | B9: 30/09/2026
A11: Código de colores | B11: Dato oficial (SRT) transcripto del material de partida, no contrastado con el original
B12: Dato periodístico (medio identificado)
B13: Dato sin fuente primaria identificada en el material (se cita la investigación adjunta); requiere verificación
B14: Dato no disponible en la fuente consultada
B15: Celda blanca con texto negro: fórmula calculada · texto verde: vínculo a otra hoja

Sheet Misiones
A1: Accidentabilidad laboral en Misiones: datos disponibles (2021-2025)
A5: Año | B5: Período | C5: Tipo de período | D5: Indicador | E5: Valor | F5: Unidad | G5: Población de referencia | H5: Sector | I5: Fuente | J5: Enlace | K5: Clasificación del dato | L5: Observaciones
A6: 2022 | B6: Enero-junio 2022 | C6: Parcial (6 meses) | D6: Casos (tipo no especificado) | E6: 3642 | F6: casos | G6: No especificada en el material | H6: No especificado en la fuente; no específico de papel y celulosa | I6: Investigación adjunta (comparación citada); fuente primaria no identificada | J6: No disponible en la fuente consultada | K6: Sin fuente primaria identificada | L6: Cifra de la comparación citada en la investigación. No se sabe si son casos notificados o con baja.
A7: 2023 | B7: Enero-junio 2023 | C7: Parcial (6 meses) | D7: Casos notificados | E7: 4031 | F7: casos notificados | G7: No especificada en el material | H7: No especificado en la fuente; no específico de papel y celulosa | I7: El Territorio (prensa, Misiones) | J7: No disponible en la fuente consultada | K7: Periodístico | L7: Cifra de prensa. Título, fecha y enlace de la nota no consignados en el material.
A8: 2024 | B8: Año 2024 | C8: Anual según la investigación (alcance por verificar) | D8: Casos (tipo no especificado) | E8: 5258 | F8: casos | G8: No especificada en el material | H8: No especificado en la fuente; no específico de papel y celulosa | I8: Investigación adjunta; fuente primaria no identificada | J8: No disponible en la fuente consultada | K8: Sin fuente primaria identificada | L8: La investigación lo consigna como “año 2024”. Ver hoja 'Indicadores' (verificación B2): no se puede confirmar que sea equivalente a ene-sep 2025.
A9: 2025 | B9: Enero-septiembre 2025 | C9: Parcial (9 meses) | D9: Casos (tipo no especificado) | E9: 5525 | F9: casos | G9: No especificada en el material | H9: No especificado en la fuente; no específico de papel y celulosa | I9: Investigación adjunta; fuente primaria no identificada | J9: No disponible en la fuente consultada | K9: Sin fuente primaria identificada | L9: Período parcial. No comparar con un año completo.
A10: 2024 | B10: Enero-septiembre 2024 | C10: Parcial (9 meses) | D10: Casos de mujeres trabajadoras | E10: 829 | F10: casos | G10: No especificada en el material | H10: No especificado en la fuente; no específico de papel y celulosa | I10: Investigación adjunta; fuente primaria no identificada | J10: No disponible en la fuente consultada | K10: Sin fuente primaria identificada | L10: Tipo de caso no especificado.
A11: 2025 | B11: Enero-septiembre 2025 | C11: Parcial (9 meses) | D11: Casos de mujeres trabajadoras | E11: 986 | F11: casos | G11: No especificada en el material | H11: No especificado en la fuente; no específico de papel y celulosa | I11: Investigación adjunta; fuente primaria no identificada | J11: No disponible en la fuente consultada | K11: Sin fuente primaria identificada | L11: Mismo período y mismo indicador que la fila anterior (comparable).
A12: 2025 | B12: Enero-septiembre 2025 | C12: Parcial (9 meses) | D12: Casos con secuelas incapacitantes | E12: 856 | F12: casos | G12: No especificada en el material | H12: No especificado en la fuente; no específico de papel y celulosa | I12: Investigación adjunta; fuente primaria no identificada | J12: No disponible en la fuente consultada | K12: Sin fuente primaria identificada | L12: Valor del período comparable de 2024: no disponible en el material.
A13: 2024-2025 | B13: Períodos comparados (no precisados) | C13: No precisado | D13: Variación informada: casos con días de baja | E13: 0.069 | F13: variación % | G13: No especificada en el material | H13: No especificado en la fuente; no específico de papel y celulosa | I13: Investigación adjunta; fuente primaria no identificada | J13: No disponible en la fuente consultada | K13: Sin fuente primaria identificada | L13: Solo se dispone de la variación informada, sin valores absolutos ni períodos exactos. No puede recalcularse.
A14: 2025 vs. período previo no precisado | B14: Ene-sep 2025 vs. período de comparación no precisado | C14: Parcial | D14: Variación informada: secuelas incapacitantes | E14: 0.283 | F14: variación % | G14: No especificada en el material | H14: No especificado en la fuente; no específico de papel y celulosa | I14: Investigación adjunta; fuente primaria no identificada | J14: No disponible en la fuente consultada | K14: Sin fuente primaria identificada | L14: Variación informada; el valor base no figura en el material. No puede recalcularse.
A15: 2024-2025 | B15: Períodos por revisar | C15: No verificado | D15: Variación informada: total de casos | E15: 0.051 | F15: variación % | G15: No especificada en el material | H15: No especificado en la fuente; no específico de papel y celulosa | I15: Investigación adjunta; fuente primaria no identificada | J15: No disponible en la fuente consultada | K15: Sin fuente primaria identificada | L15: La propia investigación advierte que los períodos deben revisarse. No se afirma que sean equivalentes. Ver 'Indicadores'.
A16: 2021 | B16: Año 2021 | C16: Anual | D16: Total de casos | E16: No disponible en la fuente consultada | F16: — | G16: No especificada en el material | H16: — | I16: — | J16: No disponible en la fuente consultada | K16: No disponible | L16: Misiones: serie 2021
A17: 2022 | B17: Año 2022 (completo) | C17: Anual | D17: Total de casos | E17: No disponible en la fuente consultada | F17: — | G17: No especificada en el material | H17: — | I17: — | J17: No disponible en la fuente consultada | K17: No disponible | L17: Solo se dispone de ene-jun 2022.
A18: 2023 | B18: Año 2023 (completo) | C18: Anual | D18: Total de casos | E18: No disponible en la fuente consultada | F18: — | G18: No especificada en el material | H18: — | I18: — | J18: No disponible en la fuente consultada | K18: No disponible | L18: Solo se dispone de ene-jun 2023.
A19: 2024 | B19: Enero-septiembre 2024 | C19: Parcial (9 meses) | D19: Total de casos | E19: No disponible en la fuente consultada | F19: — | G19: No especificada en el material | H19: — | I19: — | J19: No disponible en la fuente consultada | K19: No disponible | L19: Necesario para comparar con ene-sep 2025.
A20: 2025 | B20: Año 2025 (completo) | C20: Anual | D20: Total de casos | E20: No disponible en la fuente consultada | F20: — | G20: No especificada en el material | H20: — | I20: — | J20: No disponible en la fuente consultada | K20: No disponible | L20: Solo se dispone de ene-sep 2025.
A21: 2021-2025 | B21: Todos | C21: — | D21: Índice de incidencia de Misiones | E21: No disponible en la fuente consultada | F21: — | G21: No especificada en el material | H21: — | I21: — | J21: No disponible en la fuente consultada | K21: No disponible | L21: Falta el denominador (trabajadores cubiertos de Misiones) en todos los períodos; no se calcula.
A22: 2021-2025 | B22: Todos | C22: — | D22: Desagregación AT / EP / in itinere / reingresos | E22: No disponible en la fuente consultada | F22: — | G22: No especificada en el material | H22: — | I22: — | J22: No disponible en la fuente consultada | K22: No disponible | L22: No distinguible en las cifras del material.
A23: 2021-2025 | B23: Todos | C23: — | D23: Fallecidos en Misiones | E23: No disponible en la fuente consultada | F23: — | G23: No especificada en el material | H23: — | I23: — | J23: No disponible en la fuente consultada | K23: No disponible | L23: No consignado en el material.
A24: 2021-2025 | B24: Todos | C24: — | D24: Accidentabilidad en papel y celulosa en Misiones | E24: No disponible en la fuente consultada | F24: — | G24: No especificada en el material | H24: — | I24: — | J24: No disponible en la fuente consultada | K24: No disponible | L24: No existen datos públicos desagregados por esa actividad en el material.
A25: 2021-2025 | B25: Todos | C25: — | D25: Accidentabilidad por empresa individual | E25: No disponible en la fuente consultada | F25: — | G25: No especificada en el material | H25: — | I25: — | J25: No disponible en la fuente consultada | K25: No disponible | L25: No existen datos públicos desagregados por empresa en el material.

Sheet Industria nacional
A1: Industria manufacturera – Argentina (total nacional)
A5: Indicador | B5: Unidad | C5: 2021 | D5: 2022 | E5: 2023 | F5: 2024 | G5: 2025 | H5: Fuente | I5: Clasificación | J5: Observaciones
A6: Índice de incidencia (casos por mil trabajadores) | B6: casos / 1.000 trab. | C6: 59.5 | D6: 61.7 | E6: No disponible en la fuente consultada | F6: 52.7 | G6: No disponible en la fuente consultada | H6: SRT, según la investigación adjunta (documento exacto no consignado) | I6: Oficial (transcripto, sin contrastar) | J6: Valor publicado. Ver verificación en 'Indicadores' (B1).
A7: Fallecidos por AT y EP | B7: personas | C7: 54 | D7: 57 | E7: No disponible en la fuente consultada | F7: No disponible en la fuente consultada | G7: No disponible en la fuente consultada | H7: SRT, según la investigación adjunta (documento exacto no consignado) | I7: Oficial (transcripto, sin contrastar) | J7: AT y EP agrupados; no se separan.
A8: Casos notificados | B8: casos | C8: 75110 | D8: 82967 | E8: No disponible en la fuente consultada | F8: No disponible en la fuente consultada | G8: No disponible en la fuente consultada | H8: SRT, según la investigación adjunta (documento exacto no consignado) | I8: Oficial (transcripto, sin contrastar) | J8: No mezclar con casos con baja.
A9: Casos con baja | B9: casos | C9: 67134 | D9: 72708 | E9: No disponible en la fuente consultada | F9: No disponible en la fuente consultada | G9: No disponible en la fuente consultada | H9: SRT, según la investigación adjunta (documento exacto no consignado) | I9: Oficial (transcripto, sin contrastar) | J9: Subconjunto distinto de los notificados.
A10: Trabajadores cubiertos | B10: trabajadores | C10: 1128258 | D10: 1178397 | E10: No disponible en la fuente consultada | F10: No disponible en la fuente consultada | G10: No disponible en la fuente consultada | H10: SRT, según la investigación adjunta (documento exacto no consignado) | I10: Oficial (transcripto, sin contrastar) | J10: Denominador de los índices de incidencia.
A11: Duración media de las bajas | B11: días | C11: No disponible en la fuente consultada | D11: 37.4 | E11: No disponible en la fuente consultada | F11: No disponible en la fuente consultada | G11: No disponible en la fuente consultada | H11: SRT, según la investigación adjunta (documento exacto no consignado) | I11: Oficial (transcripto, sin contrastar) | J11: Solo 2022 disponible; no comparable con el total del sistema de otro año.
A13: Indicadores NO incluidos por no figurar en el material para la industria manufacturera: índice de frecuencia, índice de incidencia de casos mortales, duración media de bajas (2021 y 2024), cualquier dato de 2023 y 2025.

Sheet Total sistema
A1: Total del sistema – Argentina (todas las actividades)
A5: Indicador | B5: Unidad | C5: 2021 | D5: 2022 | E5: 2023 | F5: 2024 | G5: 2025 | H5: Fuente | I5: Clasificación | J5: Observaciones
A6: Índice de incidencia AT y EP en unidades productivas | B6: casos / 1.000 trab. | C6: 34.5 | D6: 37.4 | E6: No disponible en la fuente consultada | F6: 33.3 | G6: No disponible en la fuente consultada | H6: SRT, según la investigación adjunta (documento exacto no consignado) | I6: Oficial (transcripto, sin contrastar) | J6: Se transcribe la denominación del material para 2021.
A7: Trabajadores cubiertos | B7: trabajadores | C7: 9075494 | D7: 9489169 | E7: No disponible en la fuente consultada | F7: 9656664 | G7: No disponible en la fuente consultada | H7: SRT, según la investigación adjunta (documento exacto no consignado) | I7: Oficial (transcripto, sin contrastar)
A8: Índice de frecuencia | B8: casos / millón de horas | C8: 17 | D8: No disponible en la fuente consultada | E8: No disponible en la fuente consultada | F8: No disponible en la fuente consultada | G8: No disponible en la fuente consultada | H8: SRT, según la investigación adjunta (documento exacto no consignado) | I8: Oficial (transcripto, sin contrastar) | J8: Solo 2021.
A9: Duración media de las bajas | B9: días | C9: 37.6 | D9: No disponible en la fuente consultada | E9: No disponible en la fuente consultada | F9: 32.8 | G9: No disponible en la fuente consultada | H9: SRT, según la investigación adjunta (documento exacto no consignado) | I9: Oficial (transcripto, sin contrastar) | J9: 2021 y 2024.
A10: Índice de incidencia de casos mortales | B10: por millón | C10: No disponible en la fuente consultada | D10: No disponible en la fuente consultada | E10: No disponible en la fuente consultada | F10: 31.5 | G10: No disponible en la fuente consultada | H10: SRT, según la investigación adjunta (documento exacto no consignado) | I10: Oficial (transcripto, sin contrastar) | J10: Solo 2024.

Sheet Causas y riesgos
A1: Causas y riesgos – Argentina, 2024 (porcentajes NACIONALES)
A4: A. Accidentes: forma de ocurrencia
A5: Categoría | B5: Porcentaje | C5: Fuente | D5: Observaciones
A6: Caídas de personas | B6: 0.23 | C6: SRT, según la investigación adjunta (2024) | D6: Oficial (transcripto, sin contrastar)
A7: Pisadas, choques o golpes por objetos | B7: 0.22 | C7: SRT, según la investigación adjunta (2024) | D7: Oficial (transcripto, sin contrastar)
A8: Esfuerzos excesivos | B8: 0.1 | C8: SRT, según la investigación adjunta (2024) | D8: Oficial (transcripto, sin contrastar)
A9: Otras formas | B9: 0.45 | C9: SRT, según la investigación adjunta (2024) | D9: Oficial (transcripto, sin contrastar)
A10: Suma de las categorías informadas | B10: =SUM(B6:B9) -> 1 | C10: Fórmula | D10: Suma = 100%: las cuatro categorías cubren el total.
A12: B. Accidentes: agente material (categorías principales informadas)
A13: Categoría | B13: Porcentaje | C13: Fuente | D13: Observaciones
A14: Interior del ambiente de trabajo | B14: 0.3 | C14: SRT, según la investigación adjunta (2024) | D14: Oficial (transcripto, sin contrastar)
A15: Medios de transporte terrestre | B15: 0.21 | C15: SRT, según la investigación adjunta (2024) | D15: Oficial (transcripto, sin contrastar)
A16: Herramientas y utensilios | B16: 0.08 | C16: SRT, según la investigación adjunta (2024) | D16: Oficial (transcripto, sin contrastar)
A17: Suma de las categorías informadas | B17: =SUM(B14:B16) -> 0.59 | C17: Fórmula
A18: Porcentaje restante (aritmético; NO detallado en el material) | B18: =1-B17 -> 0.41 | C18: Fórmula | D18: No se sabe qué agentes lo componen; no interpretarlo como “otros”.
A20: C. Enfermedades profesionales (principales informadas)
A21: Categoría | B21: Porcentaje | C21: Fuente | D21: Observaciones
A22: Ruido | B22: 0.45 | C22: SRT, según la investigación adjunta (2024) | D22: Oficial (transcripto, sin contrastar)
A23: Posiciones forzadas y gestos repetitivos | B23: 0.25 | C23: SRT, según la investigación adjunta (2024) | D23: Oficial (transcripto, sin contrastar)
A24: Sobrecarga del uso de la voz | B24: 0.11 | C24: SRT, según la investigación adjunta (2024) | D24: Oficial (transcripto, sin contrastar)
A25: Suma de las categorías informadas | B25: =SUM(B22:B24) -> 0.81 | C25: Fórmula
A26: Porcentaje restante (aritmético; NO detallado en el material) | B26: =1-B25 -> 0.19 | C26: Fórmula | D26: No se sabe qué enfermedades lo componen.
A46: Nota: porcentajes nacionales 2024 (SRT, según la investigación adjunta). No específicos de Misiones ni de papel y celulosa. Universo (total sistema o industria) por verificar.

Sheet Indicadores
A1: Indicadores y variaciones porcentuales
A2: Variación % = (valor final − valor inicial) / valor inicial. Solo se calcula entre períodos comparables. Valores de origen vinculados a las otras hojas.
A4: A. Variaciones porcentuales
A5: ID | B5: Ámbito | C5: Indicador | D5: Período inicial | E5: Valor inicial | F5: Período final | G5: Valor final | H5: ¿Comparable? | I5: Variación calculada | J5: Variación informada en la fuente | K5: Observaciones
A6: N1 | B6: Industria nac. | C6: Índice de incidencia (por mil trab.) | D6: 2021 | E6: ='Industria nacional'!C6 -> 59.5 | F6: 2022 | G6: ='Industria nacional'!D6 -> 61.7 | H6: Sí (años consecutivos, mismo indicador) | I6: =IF(AND(ISNUMBER(E6),ISNUMBER(G6)),IF(E6<>0,(G6-E6)/E6,"No calculable"),"No calculable") -> 0.03697479 | J6: No informada | K6: Años completos consecutivos.
A7: N2 | B7: Industria nac. | C7: Fallecidos por AT y EP | D7: 2021 | E7: ='Industria nacional'!C7 -> 54 | F7: 2022 | G7: ='Industria nacional'!D7 -> 57 | H7: Sí | I7: =IF(AND(ISNUMBER(E7),ISNUMBER(G7)),IF(E7<>0,(G7-E7)/E7,"No calculable"),"No calculable") -> 0.055555556 | J7: No informada | K7: Números absolutos pequeños: interpretar con cautela.
A8: N3 | B8: Industria nac. | C8: Casos notificados | D8: 2021 | E8: ='Industria nacional'!C8 -> 75110 | F8: 2022 | G8: ='Industria nacional'!D8 -> 82967 | H8: Sí | I8: =IF(AND(ISNUMBER(E8),ISNUMBER(G8)),IF(E8<>0,(G8-E8)/E8,"No calculable"),"No calculable") -> 0.10460658 | J8: No informada | K8: Solo notificados con notificados.
A9: N4 | B9: Industria nac. | C9: Casos con baja | D9: 2021 | E9: ='Industria nacional'!C9 -> 67134 | F9: 2022 | G9: ='Industria nacional'!D9 -> 72708 | H9: Sí | I9: =IF(AND(ISNUMBER(E9),ISNUMBER(G9)),IF(E9<>0,(G9-E9)/E9,"No calculable"),"No calculable") -> 0.083027974 | J9: No informada | K9: Solo con baja con con baja.
A10: N5 | B10: Industria nac. | C10: Trabajadores cubiertos | D10: 2021 | E10: ='Industria nacional'!C10 -> 1128258 | F10: 2022 | G10: ='Industria nacional'!D10 -> 1178397 | H10: Sí | I10: =IF(AND(ISNUMBER(E10),ISNUMBER(G10)),IF(E10<>0,(G10-E10)/E10,"No calculable"),"No calculable") -> 0.044439304 | J10: No informada | K10: Crecimiento de la población cubierta.
A11: N6 | B11: Industria nac. | C11: Índice de incidencia (por mil trab.) | D11: 2022 | E11: ='Industria nacional'!D6 -> 61.7 | F11: 2024 | G11: ='Industria nacional'!F6 -> 52.7 | H11: Sí, con reserva (intervalo de 2 años; 2023 no disponible) | I11: =IF(AND(ISNUMBER(E11),ISNUMBER(G11)),IF(E11<>0,(G11-E11)/E11,"No calculable"),"No calculable") -> -0.1458671 | J11: No informada | K11: No describe la trayectoria de 2023.
A12: S1 | B12: Total sistema | C12: Índice de incidencia (por mil trab.) | D12: 2021 | E12: ='Total sistema'!C6 -> 34.5 | F12: 2022 | G12: ='Total sistema'!D6 -> 37.4 | H12: Sí | I12: =IF(AND(ISNUMBER(E12),ISNUMBER(G12)),IF(E12<>0,(G12-E12)/E12,"No calculable"),"No calculable") -> 0.084057971 | J12: No informada
A13: S2 | B13: Total sistema | C13: Índice de incidencia (por mil trab.) | D13: 2022 | E13: ='Total sistema'!D6 -> 37.4 | F13: 2024 | G13: ='Total sistema'!F6 -> 33.3 | H13: Sí, con reserva (2023 no disponible) | I13: =IF(AND(ISNUMBER(E13),ISNUMBER(G13)),IF(E13<>0,(G13-E13)/E13,"No calculable"),"No calculable") -> -0.10962567 | J13: No informada
A14: S3 | B14: Total sistema | C14: Trabajadores cubiertos | D14: 2022 | E14: ='Total sistema'!D7 -> 9489169 | F14: 2024 | G14: ='Total sistema'!F7 -> 9656664 | H14: Sí, con reserva (2023 no disponible) | I14: =IF(AND(ISNUMBER(E14),ISNUMBER(G14)),IF(E14<>0,(G14-E14)/E14,"No calculable"),"No calculable") -> 0.017651177 | J14: No informada
A15: S4 | B15: Total sistema | C15: Duración media de las bajas (días) | D15: 2021 | E15: ='Total sistema'!C9 -> 37.6 | F15: 2024 | G15: ='Total sistema'!F9 -> 32.8 | H15: Sí, con reserva (intervalo de 3 años; sin datos intermedios) | I15: =IF(AND(ISNUMBER(E15),ISNUMBER(G15)),IF(E15<>0,(G15-E15)/E15,"No calculable"),"No calculable") -> -0.12765957 | J15: No informada
A16: M1 | B16: Misiones | C16: Total de casos (enero-junio) | D16: Ene-jun 2022 | E16: =Misiones!E6 -> 3642 | F16: Ene-jun 2023 | G16: =Misiones!E7 -> 4031 | H16: Sí, con reserva: mismo período, pero el tipo de caso de 2022 no está especificado y el de 2023 es “notificados” | I16: =IF(AND(ISNUMBER(E16),ISNUMBER(G16)),IF(E16<>0,(G16-E16)/E16,"No calculable"),"No calculable") -> 0.10680945 | J16: No informada | K16: Comparación con condición: confirmar que ambas cifras miden lo mismo (notificados).
A17: M2 | B17: Misiones | C17: Casos de mujeres trabajadoras (ene-sep) | D17: Ene-sep 2024 | E17: =Misiones!E10 -> 829 | F17: Ene-sep 2025 | G17: =Misiones!E11 -> 986 | H17: Sí (mismo período e indicador) | I17: =IF(AND(ISNUMBER(E17),ISNUMBER(G17)),IF(E17<>0,(G17-E17)/E17,"No calculable"),"No calculable") -> 0.1893848 | J17: No informada | K17: Comparación válida en los términos del material.
A18: M3 | B18: Misiones | C18: Total de casos | D18: Año 2024 | E18: =Misiones!E8 -> 5258 | F18: Ene-sep 2025 | G18: =Misiones!E9 -> 5525 | H18: NO: año 2024 vs. 9 meses de 2025; equivalencia no verificada | I18: No calculable (períodos no equivalentes) | J18: 0.051 | K18: Se informa el 5,1% de la investigación, pero NO se calcula ni se presenta como variación válida. Ver B2.
A19: M4 | B19: Misiones | C19: Casos con días de baja | D19: No precisado | E19: No disponible en la fuente consultada | F19: No precisado | G19: No disponible en la fuente consultada | H19: NO: valores absolutos no disponibles | I19: No calculable | J19: 0.069 | K19: Solo se cuenta con la variación informada por la fuente.
A20: M5 | B20: Misiones | C20: Casos con secuelas incapacitantes | D20: No precisado | E20: No disponible en la fuente consultada | F20: Ene-sep 2025 | G20: =Misiones!E12 -> 856 | H20: NO: falta el valor del período inicial | I20: No calculable | J20: 0.283 | K20: No se despeja el valor base a partir de la variación informada (sería una estimación).
A22: B. Verificaciones
A23: B1. ¿Con qué numerador se calcula el índice de incidencia nacional de la industria? (índice = casos / trabajadores cubiertos × 1.000)
A24: ID | B24: Año | C24: Casos con baja | D24: Casos notificados | E24: Trabajadores cubiertos | F24: Índice calc. con “casos con baja” | G24: Índice calc. con “casos notificados” | H24: Índice publicado | I24: Diferencia (con baja − publicado) | K24: Lectura
A25: B1-2021 | B25: 2021 | C25: ='Industria nacional'!C9 -> 67134 | D25: ='Industria nacional'!C8 -> 75110 | E25: ='Industria nacional'!C10 -> 1128258 | F25: =C25/E25*1000 -> 59.502348 | G25: =D25/E25*1000 -> 66.571653 | H25: ='Industria nacional'!C6 -> 59.5 | I25: =F25-H25 -> 0.0023478672 | K25: El índice publicado coincide con casos CON BAJA / trabajadores, no con notificados. Por eso se cita “casos con baja por mil trabajadores”.
A26: B1-2022 | B26: 2022 | C26: ='Industria nacional'!D9 -> 72708 | D26: ='Industria nacional'!D8 -> 82967 | E26: ='Industria nacional'!D10 -> 1178397 | F26: =C26/E26*1000 -> 61.700768 | G26: =D26/E26*1000 -> 70.406663 | H26: ='Industria nacional'!D6 -> 61.7 | I26: =F26-H26 -> 0.00076807731 | K26: El índice publicado coincide con casos CON BAJA / trabajadores, no con notificados. Por eso se cita “casos con baja por mil trabajadores”.
A28: B2. Verificación aritmética de la variación total informada para Misiones (5,1%)
A29: ID | C29: Valor “año 2024” | D29: Valor “ene-sep 2025” | E29: Variación aritmética entre ambos | F29: Variación informada | G29: Diferencia | K29: Lectura
A30: B2 | C30: =Misiones!E8 -> 5258 | D30: =Misiones!E9 -> 5525 | E30: =(D30-C30)/C30 -> 0.050779764 | F30: =Misiones!E15 -> 0.051 | G30: =E30-F30 -> -0.00022023583 | K30: El 5,1% informado coincide numéricamente con comparar las dos cifras tal como están rotuladas (año 2024 vs. ene-sep 2025). Eso implica comparar 12 con 9 meses, o bien que 5.258 corresponda en realidad a ene-sep 2024. El material no permite resolverlo: verificar en la fuente. La variación no se usa como válida.
A32: B3. Índice de incidencia de Misiones
A33: B3 | B33: Misiones | C33: No calculable: falta el denominador (trabajadores cubiertos en Misiones) en todos los períodos. No se usó ninguna estimación.
A35: C. Gráficos (solo datos comparables)
A37: Gráfico 1. Índice de incidencia: industria manufacturera vs. total del sistema (Argentina)
B38: Año | C38: Industria manufacturera | D38: Total del sistema
B39: 2021 | C39: ='Industria nacional'!C6 -> 59.5 | D39: ='Total sistema'!C6 -> 34.5
B40: 2022 | C40: ='Industria nacional'!D6 -> 61.7 | D40: ='Total sistema'!D6 -> 37.4
B41: 2024 | C41: ='Industria nacional'!F6 -> 52.7 | D41: ='Total sistema'!F6 -> 33.3
A57: Gráfico 2. Misiones: casos en enero-junio de 2022 y 2023
B58: Período | C58: Casos
B59: Ene-jun 2022 | C59: =Misiones!E6 -> 3642
B60: Ene-jun 2023 | C60: =Misiones!E7 -> 4031
A77: Gráfico 3. Misiones: casos de mujeres trabajadoras, enero-septiembre
...

Sheet Fuentes
A1: Fuentes utilizadas
A4: N° | B4: Institución o medio | C4: Título del documento | D4: Año | E4: Enlace | F4: Tipo de fuente | G4: Datos que respalda | H4: Observaciones
A5: 1 | B5: Superintendencia de Riesgos del Trabajo (SRT), Argentina | C5: Estadísticas/informes de accidentabilidad laboral (título exacto no consignado en el material) | D5: 2021-2025 (según dato) | E5: https://www.srt.gob.ar (sitio institucional; documento específico no verificado) | F5: Oficial | G5: Indicadores nacionales de industria manufacturera y total del sistema; causas y riesgos 2024; posiblemente cifras de Misiones | H5: Transcripto desde la investigación adjunta. Consultar el documento original para completar título y enlace.
A6: 2 | B6: El Territorio (prensa, Misiones) | C6: Nota sobre casos notificados en Misiones, enero-junio 2023 (título no consignado) | D6: 2023 | E6: No disponible en la fuente consultada | F6: Periodística | G6: Misiones, ene-jun 2023: 4.031 casos notificados | H6: Completar título, fecha y enlace de la nota.
A7: 3 | B7: Investigación adjunta por la persona usuaria | C7: Material de partida (documento de investigación) | D7: 2026 (elaboración) | E7: No disponible en la fuente consultada | F7: Técnica (secundaria) | G7: Cifras de Misiones 2022, 2024 y 2025; mujeres; variaciones informadas; limitaciones | H7: Fuente secundaria: no identifica la fuente primaria de cada cifra de Misiones. Verificar antes de citar.

Sheet Limitaciones
A1: Limitaciones de los datos
A4: N° | B4: Tema | C4: Qué no está disponible | D4: Por qué limita las conclusiones
A5: 1 | B5: Serie de Misiones | C5: No hay serie anual completa y homogénea 2021-2025 (solo ene-jun 2022, ene-jun 2023, año 2024 y ene-sep 2025). | D5: No puede describirse la tendencia anual de Misiones ni compararse años completos con períodos parciales.
A6: 2 | B6: Períodos de 2024 y 2025 | C6: No se verifica si “año 2024” y “ene-sep 2025” son comparables; el 5,1% informado equivale a dividir esas dos cifras (hoja 'Indicadores', B2). | D6: Puede compararse un año completo con nueve meses. Por eso no se afirma un aumento interanual.
A7: 3 | B7: Tipo de casos | C7: Las cifras de Misiones no especifican si son AT, EP, in itinere, reingresos, notificados o con baja (salvo “notificados” en 2023). | D7: Sumar o comparar cifras de distinta naturaleza produciría resultados inválidos.
A8: 4 | B8: Denominador en Misiones | C8: No hay trabajadores cubiertos de Misiones en el material. | D8: No puede calcularse el índice de incidencia provincial ni compararlo con el nacional.
A9: 5 | B9: Papel y celulosa | C9: No existen datos públicos desagregados por actividad en Misiones en el material. | D9: Los datos de industria manufacturera nacional no pueden atribuirse a papel y celulosa: incluyen actividades muy distintas.
A10: 6 | B10: Empresas individuales | C10: No hay datos públicos por empresa. | D10: No pueden evaluarse empresas concretas ni su desempeño.
A11: 7 | B11: Datos nacionales incompletos | C11: Industria: sin 2023 y 2025; 2024 solo con índice. Total sistema: datos parciales por año. | D11: Las comparaciones nacionales usan solo años disponibles, algunos no consecutivos.
A12: 8 | B12: Universo de causas 2024 | C12: No se aclara si los porcentajes de causas son del total del sistema o de la industria; los agentes y enfermedades suman menos de 100%. | D12: No pueden asignarse a la industria ni a Misiones, ni interpretar el resto no detallado.
A13: 9 | B13: Relación con el sistema de ART | C13: No hay datos por aseguradora (ART), cobertura provincial, prevención, inspecciones ni siniestralidad por ART. | D13: Los datos no permiten evaluar el desempeño de las ART ni causalidad entre el sistema de ART y la accidentabilidad.
A14: 10 | B14: Verificación de fuentes | C14: Sin acceso a internet: ninguna cifra se contrastó con el original; faltan títulos y enlaces exactos. | D14: Todas las cifras deben verificarse antes de la entrega.
